Workbook
Name wDiscountWeight: '09_KPI_StoreScore'!$B$9
Name wGrowthWeight: '09_KPI_StoreScore'!$B$10
Name wMarginWeight: '09_KPI_StoreScore'!$B$6
Name wReturnWeight: '09_KPI_StoreScore'!$B$8
Name wTrendWeight: '09_KPI_StoreScore'!$B$7

Sheet 00_Cover_ReadMe
B2: NOVA RETAIL — MIS REPORTING SYSTEM
B3: Profitability Monitoring, Margin Volatility & Performance Diagnostic
B6: Business Problem
B7: Nova Retail's leadership lacks a centralized, consistent MIS system to identify where profitability is unstable across regions, stores, categories, returns, and promotions.
B9: Scope & Data Source
B10: Source: Nova Retail ERP dataset (15 tables, Jan 2021 - Dec 2024, verified zero orphan keys). This workbook is built entirely from that dataset. No figures are estimated, assumed, or fabricated.
B12: How This Workbook Is Built
B13: Model_ sheets = cleaned and aggregated reporting layer produced from the ERP data.*
B14: KPI_* sheets = Business logic layer. Every cell is a live formula referencing Model_* tables (SUMIFS / INDEX-MATCH / LET). No hardcoded numbers.
B15: Report_* sheets = Aggregated views + native charts answering each locked business question.
B16: Dashboard = Executive reporting layer; KPI values and visuals are linked to calculated data, with no manually typed business numbers.
B17: Insights = Formula-generated sentences, built from live KPI cells.
... B31: No inventory/warehouse table, no freight/logistics cost, no supplier lead-time data, no employee cost data, no store-level sales target exists in source data.

Sheet 01_Model_Overall_Month
A3: year | B3: month | C3: ym | D3: revenue | E3: cost | F3: orders | G3: margin | H3: margin_pct
A4: 2021 | B4: 1 | C4: 2021-01 | D4: 196258182 | E4: 1.775816e+08 | F4: 3043 | G4: 18676578 | H4: 0.0952
A5: 2021 | B5: 2 | C5: 2021-02 | D5: 178833814 | E5: 1.5661328e+08 | F5: 2736 | G5: 22220536 | H5: 0.1243
A6: 2021 | B6: 3 | C6: 2021-03 | D6: 215985173 | E6: 1.8131914e+08 | F6: 3081 | G6: 34666032 | H6: 0.1605
A7: 2021 | B7: 4 | C7: 2021-04 | D7: 222112137 | E7: 1.9532314e+08 | F7: 3305 | G7: 26788996 | H7: 0.1206
A8: 2021 | B8: 5 | C8: 2021-05 | D8: 249111988 | E8: 2.1764874e+08 | F8: 3746 | G8: 31463253 | H8: 0.1263
A9: 2021 | B9: 6 | C9: 2021-06 | D9: 232257296 | E9: 2.0256513e+08 | F9: 3505 | G9: 29692161 | H9: 0.1278
A10: 2021 | B10: 7 | C10: 2021-07 | D10: 219645765 | E10: 1.9300395e+08 | F10: 3378 | G10: 26641819 | H10: 0.1213
A11: 2021 | B11: 8 | C11: 2021-08 | D11: 243118909 | E11: 2.0546319e+08 | F11: 3448 | G11: 37655723 | H11: 0.1549
A12: 2021 | B12: 9 | C12: 2021-09 | D12: 238960088 | E12: 2.0778255e+08 | F12: 3625 | G12: 31177540 | H12: 0.1305
A13: 2021 | B13: 10 | C13: 2021-10 | D13: 351828947 | E13: 2.9714688e+08 | F13: 5074 | G13: 54682070 | H13: 0.1554
A14: 2021 | B14: 11 | C14: 2021-11 | D14: 342872940 | E14: 2.8375449e+08 | F14: 4967 | G14: 59118451 | H14: 0.1724
A15: 2021 | B15: 12 | C15: 2021-12 | D15: 341260894 | E15: 2.8675124e+08 | F15: 4787 | G15: 54509659 | H15: 0.1597
... A51: 2024 | B51: 12 | C51: 2024-12 | D51: 700106315 | E51: 5.6078178e+08 | F51: 9569 | G51: 1.3932454e+08 | H51: 0.199

Sheet 01_Model_Region_Month
A1: 01_Model_Region_Month — ETL output (materialized). Source: Power Query joins documented in PowerQuery_DAX_Specification.md
A3: region_id | B3: region_name | C3: zone | D3: year | E3: month | F3: ym | G3: revenue | H3: cost | I3: orders | J3: margin | K3: margin_pct | L3: target_amount | M3: achievement_pct
A4: 1 | B4: Delhi NCR | C4: North | D4: 2021 | E4: 1 | F4: 2021-01 | G4: 12380981 | H4: 11087564 | I4: 213 | J4: 1293417.3 | K4: 0.1045 | L4: 10697000 | M4: 1.1574
A5: 1 | B5: Delhi NCR | C5: North | D5: 2021 | E5: 2 | F5: 2021-02 | G5: 10959141 | H5: 9670859.7 | I5: 174 | J5: 1288281.3 | K5: 0.1176 | L5: 9457000 | M5: 1.1588
A6: 1 | B6: Delhi NCR | C6: North | D6: 2021 | E6: 3 | F6: 2021-03 | G6: 15822191 | H6: 13111980 | I6: 208 | J6: 2710210.7 | K6: 0.1713 | L6: 13587000 | M6: 1.1645
A7: 1 | B7: Delhi NCR | C7: North | D7: 2021 | E7: 4 | F7: 2021-04 | G7: 16070756 | H7: 14418970 | I7: 245 | J7: 1651785.9 | K7: 0.1028 | L7: 13088000 | M7: 1.2279
A8: 1 | B8: Delhi NCR | C8: North | D8: 2021 | E8: 5 | F8: 2021-05 | G8: 18356840 | H8: 15878881 | I8: 270 | J8: 2477959.3 | K8: 0.135 | L8: 16709000 | M8: 1.0986
A9: 1 | B9: Delhi NCR | C9: North | D9: 2021 | E9: 6 | F9: 2021-06 | G9: 13950991 | H9: 12055818 | I9: 241 | J9: 1895172.6 | K9: 0.1358 | L9: 12129000 | M9: 1.1502
A10: 1 | B10: Delhi NCR | C10: North | D10: 2021 | E10: 7 | F10: 2021-07 | G10: 16941381 | H10: 14926802 | I10: 256 | J10: 2014578.9 | K10: 0.1189 | L10: 14875000 | M10: 1.1389
A11: 1 | B11: Delhi NCR | C11: North | D11: 2021 | E11: 8 | F11: 2021-08 | G11: 16036560 | H11: 13628002 | I11: 250 | J11: 2408558.2 | K11: 0.1502 | L11: 13400000 | M11: 1.1968
A12: 1 | B12: Delhi NCR | C12: North | D12: 2021 | E12: 9 | F12: 2021-09 | G12: 15839935 | H12: 13850584 | I12: 242 | J12: 1989351.1 | K12: 0.1256 | L12: 13365000 | M12: 1.1852
A13: 1 | B13: Delhi NCR | C13: North | D13: 2021 | E13: 10 | F13: 2021-10 | G13: 24202697 | H13: 20462867 | I13: 350 | J13: 3739830.1 | K13: 0.1545 | L13: 22084000 | M13: 1.0959
A14: 1 | B14: Delhi NCR | C14: North | D14: 2021 | E14: 11 | F14: 2021-11 | G14: 23510204 | H14: 19398145 | I14: 357 | J14: 4112059 | K14: 0.1749 | L14: 19722000 | M14: 1.1921
A15: 1 | B15: Delhi NCR | C15: North | D15: 2021 | E15: 12 | F15: 2021-12 | G15: 27045888 | H15: 22680534 | I15: 346 | J15: 4365353.6 | K15: 0.1614 | L15: 22318000 | M15: 1.2118
... A579: 9 | B579: West Bengal | C579: East | D579: 2024 | E579: 12 | F579: 2024-12 | G579: 102763407 | H579: 82395550 | I579: 1401 | J579: 20367857 | K579: 0.1982 | L579: 90056000 | M579: 1.1411

Sheet 01_Model_Store_Month
A1: 01_Model_Store_Month — ETL output (materialized). Source: Power Query joins documented in PowerQuery_DAX_Specification.md
A3: store_id | B3: store_name | C3: region_id | D3: region_name | E3: year | F3: month | G3: ym | H3: revenue | I3: cost | J3: orders | K3: discount_leak | L3: catalog_value | M3: margin | N3: margin_pct | O3: return_count | P3: refund_amount
A4: 82 | B4: Nova Retail - Ahmedabad Flagship | C4: 4 | D4: Gujarat | E4: 2021 | F4: 1 | G4: 2021-01 | H4: 4451189 | I4: 4074748.1 | J4: 79 | K4: 826353 | L4: 5268320 | M4: 376440.92 | N4: 0.0846 | O4: 4 | P4: 86498
A5: 82 | B5: Nova Retail - Ahmedabad Flagship | C5: 4 | D5: Gujarat | E5: 2021 | F5: 2 | G5: 2021-02 | H5: 4971793 | I5: 4327551.4 | J5: 88 | K5: 610040 | L5: 5560190 | M5: 644241.56 | N5: 0.1296 | O5: 5 | P5: 173374
A6: 82 | B6: Nova Retail - Ahmedabad Flagship | C6: 4 | D6: Gujarat | E6: 2021 | F6: 3 | G6: 2021-03 | H6: 5640965 | I6: 4593880.5 | J6: 68 | K6: 303127 | L6: 5919100 | M6: 1047084.5 | N6: 0.1856 | O6: 2 | P6: 7560
A7: 82 | B7: Nova Retail - Ahmedabad Flagship | C7: 4 | D7: Gujarat | E7: 2021 | F7: 4 | G7: 2021-04 | H7: 5911953 | I7: 5071904 | J7: 94 | K7: 608849 | L7: 6503760 | M7: 840049.03 | N7: 0.1421 | O7: 7 | P7: 174962
A8: 82 | B8: Nova Retail - Ahmedabad Flagship | C8: 4 | D8: Gujarat | E8: 2021 | F8: 5 | G8: 2021-05 | H8: 5659236 | I8: 5081764.6 | J8: 90 | K8: 846908 | L8: 6478060 | M8: 577471.41 | N8: 0.102 | O8: 11 | P8: 292299
A9: 82 | B9: Nova Retail - Ahmedabad Flagship | C9: 4 | D9: Gujarat | E9: 2021 | F9: 6 | G9: 2021-06 | H9: 6963757 | I9: 6069429.2 | J9: 111 | K9: 754315 | L9: 7699210 | M9: 894327.85 | N9: 0.1284 | O9: 2 | P9: 57497
A10: 82 | B10: Nova Retail - Ahmedabad Flagship | C10: 4 | D10: Gujarat | E10: 2021 | F10: 7 | G10: 2021-07 | H10: 6995955 | I10: 6004837.7 | J10: 96 | K10: 773574 | L10: 7748250 | M10: 991117.34 | N10: 0.1417 | O10: 8 | P10: 485994
A11: 82 | B11: Nova Retail - Ahmedabad Flagship | C11: 4 | D11: Gujarat | E11: 2021 | F11: 8 | G11: 2021-08 | H11: 6693632 | I11: 5829583.8 | J11: 97 | K11: 759863 | L11: 7431370 | M11: 864048.23 | N11: 0.1291 | O11: 8 | P11: 222499
A12: 82 | B12: Nova Retail - Ahmedabad Flagship | C12: 4 | D12: Gujarat | E12: 2021 | F12: 9 | G12: 2021-09 | H12: 6657458 | I12: 5866035.6 | J12: 99 | K12: 917483 | L12: 7561620 | M12: 791422.39 | N12: 0.1189 | O12: 15 | P12: 153855
A13: 82 | B13: Nova Retail - Ahmedabad Flagship | C13: 4 | D13: Gujarat | E13: 2021 | F13: 10 | G13: 2021-10 | H13: 9008786 | I13: 7619380 | J13: 121 | K13: 641819 | L13: 9618710 | M13: 1389406 | N13: 0.1542 | O13: 9 | P13: 314728
A14: 82 | B14: Nova Retail - Ahmedabad Flagship | C14: 4 | D14: Gujarat | E14: 2021 | F14: 11 | G14: 2021-11 | H14: 9076033 | I14: 7614981.2 | J14: 138 | K14: 731062 | L14: 9785670 | M14: 1461051.8 | N14: 0.161 | O14: 8 | P14: 321018
A15: 82 | B15: Nova Retail - Ahmedabad Flagship | C15: 4 | D15: Gujarat | E15: 2021 | F15: 12 | G15: 2021-12 | H15: 10251721 | I15: 8574234 | J15: 142 | K15: 803057 | L15: 11019830 | M15: 1677487 | N15: 0.1636 | O15: 10 | P15: 239266
... A5762: 40 | B5762: Nova Retail - Warangal Standard | C5762: 7 | D5762: Telangana-AP | E5762: 2024 | F5762: 12 | G5762: 2024-12 | H5762: 3816993 | I5762: 3129538.7 | J5762: 51 | K5762: 119382 | L5762: 3926190 | M5762: 687454.32 | N5762: 0.1801 | O5762: 3 | P5762: 13931

Sheet 01_Model_Store_Score
A1: 01_Model_Store_Score — ETL output (materialized). Source: Power Query joins documented in PowerQuery_DAX_Specification.md
A3: store_id | B3: store_name | C3: region_id | D3: region_name | E3: revenue_last6 | F3: cost_last6 | G3: discount_leak_last6 | H3: catalog_value_last6 | I3: order_count_last6 | J3: lines_last6 | K3: margin_last6 | L3: margin_pct_last6 | M3: discount_leak_pct_last6 | N3: revenue_prior6 | O3: cost_prior6 | P3: discount_leak_prior6 | Q3: catalog_value_prior6 | R3: order_count_prior6 | S3: lines_prior6 | T3: margin_prior6 | U3: margin_pct_prior6 | V3: discount_leak_pct_prior6 | W3: return_rate_last6 | X3: revenue_growth_pct | Y3: margin_trend_pp
A4: 82 | B4: Nova Retail - Ahmedabad Flagship | C4: 4 | D4: Gujarat | E4: 101854767 | F4: 83518150 | G4: 5903840 | H4: 107393300 | I4: 1433 | J4: 3180 | K4: 18336617 | L4: 0.18 | M4: 0.055 | N4: 68384180 | O4: 58998120 | P4: 7842824 | Q4: 75943640 | R4: 1105 | S4: 2392 | T4: 9386059.9 | U4: 0.1373 | V4: 0.1033 | W4: 0.0343 | X4: 0.4894 | Y4: 0.04
A5: 42 | B5: Nova Retail - Ahmedabad Standard | C5: 4 | D5: Gujarat | E5: 23674489 | F5: 19305903 | G5: 1430237 | H5: 25027930 | I5: 330 | J5: 761 | K5: 4368586.3 | L5: 0.1845 | M5: 0.0571 | N5: 17251617 | O5: 15170081 | P5: 2132533 | Q5: 19324710 | R5: 253 | S5: 553 | T5: 2081536.4 | U5: 0.1207 | V5: 0.1104 | W5: 0.0342 | X5: 0.3723 | Y5: 0.06
A6: 33 | B6: Nova Retail - Amritsar Compact | C6: 2 | D6: Punjab-Haryana | E6: 8773684 | F6: 7092388.6 | G6: 501149 | H6: 9240140 | I6: 143 | J6: 310 | K6: 1681295.4 | L6: 0.1916 | M6: 0.0542 | N6: 6958758 | O6: 6123577.2 | P6: 894536 | Q6: 7844010 | R6: 106 | S6: 247 | T6: 835180.79 | U6: 0.12 | V6: 0.114 | W6: 0.0484 | X6: 0.2608 | Y6: 0.07
A7: 105 | B7: Nova Retail - Amritsar Compact | C7: 2 | D7: Punjab-Haryana | E7: 18980924 | F7: 15405472 | G7: 906444 | H7: 19785650 | I7: 297 | J7: 644 | K7: 3575451.6 | L7: 0.1884 | M7: 0.0458 | N7: 14960019 | O7: 12854057 | P7: 1647468 | Q7: 16542910 | R7: 225 | S7: 494 | T7: 2105961.7 | U7: 0.1408 | V7: 0.0996 | W7: 0.0248 | X7: 0.2688 | Y7: 0.05
A8: 3 | B8: Nova Retail - Amritsar Flagship | C8: 2 | D8: Punjab-Haryana | E8: 34867529 | F8: 28562230 | G8: 2192997 | H8: 36961930 | I8: 482 | J8: 1072 | K8: 6305299.3 | L8: 0.1808 | M8: 0.0593 | N8: 26569033 | O8: 22786936 | P8: 2874276 | Q8: 29364600 | R8: 401 | S8: 858 | T8: 3782096.8 | U8: 0.1423 | V8: 0.0979 | W8: 0.0345 | X8: 0.3123 | Y8: 0.04
A9: 60 | B9: Nova Retail - Amritsar Standard | C9: 2 | D9: Punjab-Haryana | E9: 13824310 | F9: 11324838 | G9: 844619 | H9: 14625540 | I9: 213 | J9: 480 | K9: 2499471.9 | L9: 0.1808 | M9: 0.0577 | N9: 12195516 | O9: 10147357 | P9: 997981 | Q9: 13150730 | R9: 173 | S9: 387 | T9: 2048159.1 | U9: 0.1679 | V9: 0.0759 | W9: 0.0333 | X9: 0.1336 | Y9: 0.01
A10: 72 | B10: Nova Retail - Amritsar Standard | C10: 2 | D10: Punjab-Haryana | E10: 16754805 | F10: 13740100 | G10: 1061112 | H10: 17747390 | I10: 222 | J10: 500 | K10: 3014704.7 | L10: 0.1799 | M10: 0.0598 | N10: 11483018 | O10: 10050421 | P10: 1409173 | Q10: 12861630 | R10: 173 | S10: 358 | T10: 1432597.3 | U10: 0.1248 | V10: 0.1096 | W10: 0.036 | X10: 0.4591 | Y10: 0.06
A11: 7 | B11: Nova Retail - Bengaluru Compact | C11: 5 | D11: Karnataka | E11: 19550260 | F11: 15947157 | G11: 1066155 | H11: 20556530 | I11: 293 | J11: 638 | K11: 3603103.2 | L11: 0.1843 | M11: 0.0519 | N11: 15020882 | O11: 12834763 | P11: 1619194 | Q11: 16596250 | R11: 224 | S11: 515 | T11: 2186118.8 | U11: 0.1455 | V11: 0.0976 | W11: 0.0266 | X11: 0.3015 | Y11: 0.04
A12: 68 | B12: Nova Retail - Bengaluru Standard | C12: 5 | D12: Karnataka | E12: 36935554 | F12: 30517359 | G12: 2375158 | H12: 39195260 | I12: 502 | J12: 1083 | K12: 6418194.6 | L12: 0.1738 | M12: 0.0606 | N12: 27064300 | O12: 23247125 | P12: 3042016 | Q12: 30017640 | R12: 394 | S12: 888 | T12: 3817175.1 | U12: 0.141 | V12: 0.1013 | W12: 0.0305 | X12: 0.3647 | Y12: 0.03
A13: 98 | B13: Nova Retail - Bengaluru Standard | C13: 5 | D13: Karnataka | E13: 73810081 | F13: 60735367 | G13: 4594132 | H13: 78187120 | I13: 1029 | J13: 2283 | K13: 13074714 | L13: 0.1771 | M13: 0.0588 | N13: 56795916 | O13: 48979436 | P13: 6495680 | Q13: 63110730 | R13: 794 | S13: 1771 | T13: 7816480.2 | U13: 0.1376 | V13: 0.1029 | W13: 0.0385 | X13: 0.2996 | Y13: 0.04
A14: 90 | B14: Nova Retail - Bhopal Standard | C14: 11 | D14: Madhya Pradesh | E14: 15836198 | F14: 13039316 | G14: 895046 | H14: 16667180 | I14: 217 | J14: 486 | K14: 2796882.3 | L14: 0.1766 | M14: 0.0537 | N14: 8309214 | O14: 7084729.7 | P14: 861467 | Q14: 9136840 | R14: 147 | S14: 321 | T14: 1224484.3 | U14: 0.1474 | V14: 0.0943 | W14: 0.0226 | X14: 0.9059 | Y14: 0.03
A15: 20 | B15: Nova Retail - Bhubaneswar Standard | C15: 10 | D15: Odisha-Jharkhand | E15: 36652982 | F15: 30274627 | G15: 2341872 | H15: 38903040 | I15: 481 | J15: 1089 | K15: 6378355 | L15: 0.174 | M15: 0.0602 | N15: 24079752 | O15: 20850556 | P15: 2802787 | Q15: 26783760 | R15: 352 | S15: 770 | T15: 3229196.1 | U15: 0.1341 | V15: 0.1046 | W15: 0.0349 | X15: 0.5221 | Y15: 0.04
... A123: 40 | B123: Nova Retail - Warangal Standard | C123: 7 | D123: Telangana-AP | E123: 16126760 | F123: 13532496 | G123: 1187337 | H123: 17266820 | I123: 235 | J123: 499 | K123: 2594264.4 | L123: 0.1609 | M123: 0.0688 | N123: 9924161 | O123: 8440025.4 | P123: 1134022 | Q123: 11021690 | R123: 183 | S123: 385 | T123: 1484135.6 | U123: 0.1495 | V123: 0.1029 | W123: 0.022 | X123: 0.625 | Y123: 0.01

Sheet 01_Model_Category
A1: 01_Model_Category — ETL output (materialized). Source: Power Query joins documented in PowerQuery_DAX_Specification.md
A3: category_id | B3: category_name | C3: category_group | D3: revenue | E3: cost | F3: discount_leak | G3: catalog_value | H3: lines | I3: margin | J3: margin_pct | K3: discount_leak_pct | L3: return_count | M3: refund_amount | N3: return_rate | O3: revenue_share
A4: 6 | B4: Refrigerators | C4: Appliances | D4: 4382590644 | E4: 3.8491109e+09 | F4: 477412556 | G4: 4845220420 | H4: 60041 | I4: 5.3347975e+08 | J4: 0.1217 | K4: 0.0985 | L4: 2129 | M4: 139694518 | N4: 0.0355 | O4: 0.2321
A5: 2 | B5: Laptops & Computers | C5: Electronics | D5: 2977044772 | E5: 2.8067264e+09 | F5: 327405596 | G5: 3294481190 | H5: 23849 | I5: 1.7031837e+08 | J5: 0.0572 | K5: 0.0994 | L5: 1108 | M5: 120142131 | N5: 0.0465 | O5: 0.1577
A6: 3 | B6: Televisions | C6: Electronics | D6: 2296118310 | E6: 2.0218053e+09 | F6: 250368359 | G6: 2538567220 | H6: 38075 | I6: 2.7431298e+08 | J6: 0.1195 | K6: 0.0986 | L6: 1575 | M6: 88979549 | N6: 0.0414 | O6: 0.1216
A7: 14 | B7: Furniture | C7: Home & Living | D7: 1907350207 | E7: 1.6011459e+09 | F7: 209518887 | G7: 2110496580 | H7: 36122 | I7: 3.0620428e+08 | J7: 0.1605 | K7: 0.0993 | L7: 1131 | M7: 59141680 | N7: 0.0313 | O7: 0.101
A8: 1 | B8: Mobiles & Accessories | C8: Electronics | D8: 1718375549 | E8: 1.512548e+09 | F8: 186700048 | G8: 1899178170 | H8: 30469 | I8: 2.0582759e+08 | J8: 0.1198 | K8: 0.0983 | L8: 1326 | M8: 69832084 | N8: 0.0435 | O8: 0.091
A9: 5 | B9: Air Conditioners & Coolers | C9: Appliances | D9: 1462422495 | E9: 1.3095052e+09 | F9: 161801886 | G9: 1619237220 | H9: 20282 | I9: 1.5291731e+08 | J9: 0.1046 | K9: 0.0999 | L9: 730 | M9: 47019318 | N9: 0.036 | O9: 0.0775
A10: 7 | B10: Washing Machines | C10: Appliances | D10: 1242288851 | E10: 1.0986735e+09 | F10: 134651075 | G10: 1372667370 | H10: 20087 | I10: 1.4361536e+08 | J10: 0.1156 | K10: 0.0981 | L10: 682 | M10: 39892561 | N10: 0.034 | O10: 0.0658
A11: 8 | B11: Kitchen Appliances | C11: Appliances | D11: 602723939 | E11: 4.3512172e+08 | F11: 65733883 | G11: 666395200 | H11: 36206 | I11: 1.6760222e+08 | J11: 0.2781 | K11: 0.0986 | L11: 1037 | M11: 16974845 | N11: 0.0286 | O11: 0.0319
A12: 4 | B12: Home Audio | C12: Electronics | D12: 520527346 | E12: 4.2355083e+08 | F12: 56856404 | G12: 575620000 | H12: 28038 | I12: 96976521 | J12: 0.1863 | K12: 0.0988 | L12: 1084 | M12: 18808093 | N12: 0.0387 | O12: 0.0276
A13: 9 | B13: Heaters & Winter Appliances | C13: Appliances | D13: 258134495 | E13: 1.9102397e+08 | F13: 28051708 | G13: 285298830 | H13: 26198 | I13: 67110525 | J13: 0.26 | K13: 0.0983 | L13: 703 | M13: 6392296 | N13: 0.0268 | O13: 0.0137
A14: 13 | B14: Footwear | C14: Apparel | D14: 218483178 | E14: 1.4561926e+08 | F14: 24009501 | G14: 241743290 | H14: 25921 | I14: 72863913 | J14: 0.3335 | K14: 0.0993 | L14: 1751 | M14: 12659306 | N14: 0.0676 | O14: 0.0116
A15: 20 | B15: Festive & Gifting | C15: Seasonal | D15: 216122731 | E15: 1.4100408e+08 | F15: 23569987 | G15: 238954570 | H15: 41399 | I15: 75118653 | J15: 0.3476 | K15: 0.0986 | L15: 1238 | M15: 6073270 | N15: 0.0299 | O15: 0.0114
... A23: 17 | B23: Groceries & Staples | C23: Grocery | D23: 45075426 | E23: 41114892 | F23: 4946330 | G23: 49867370 | H23: 32688 | I23: 3960534.1 | J23: 0.0879 | K23: 0.0992 | L23: 244 | M23: 278695 | N23: 0.0075 | O23: 0.0024

Sheet 01_Model_Category_Month
A1: 01_Model_Category_Month — ETL output (materialized). Source: Power Query joins documented in PowerQuery_DAX_Specification.md
A3: category_id | B3: category_name | C3: ym | D3: year | E3: month | F3: revenue | G3: cost | H3: margin_pct
A4: 1 | B4: Mobiles & Accessories | C4: 2021-01 | D4: 2021 | E4: 1 | F4: 17107104 | G4: 15684713 | H4: 0.0831
A5: 1 | B5: Mobiles & Accessories | C5: 2021-02 | D5: 2021 | E5: 2 | F5: 16014997 | G5: 14223241 | H5: 0.1119
A6: 1 | B6: Mobiles & Accessories | C6: 2021-03 | D6: 2021 | E6: 3 | F6: 18291486 | G6: 15624253 | H6: 0.1458
A7: 1 | B7: Mobiles & Accessories | C7: 2021-04 | D7: 2021 | E7: 4 | F7: 18638974 | G7: 16829238 | H7: 0.0971
A8: 1 | B8: Mobiles & Accessories | C8: 2021-05 | D8: 2021 | E8: 5 | F8: 21969464 | G8: 19467092 | H8: 0.1139
A9: 1 | B9: Mobiles & Accessories | C9: 2021-06 | D9: 2021 | E9: 6 | F9: 21149075 | G9: 19093382 | H9: 0.0972
A10: 1 | B10: Mobiles & Accessories | C10: 2021-07 | D10: 2021 | E10: 7 | F10: 20971192 | G10: 18804495 | H10: 0.1033
A11: 1 | B11: Mobiles & Accessories | C11: 2021-08 | D11: 2021 | E11: 8 | F11: 21807094 | G11: 18694725 | H11: 0.1427
A12: 1 | B12: Mobiles & Accessories | C12: 2021-09 | D12: 2021 | E12: 9 | F12: 22562520 | G12: 20072668 | H12: 0.1104
A13: 1 | B13: Mobiles & Accessories | C13: 2021-10 | D13: 2021 | E13: 10 | F13: 33204464 | G13: 28787595 | H13: 0.133
A14: 1 | B14: Mobiles & Accessories | C14: 2021-11 | D14: 2021 | E14: 11 | F14: 33878499 | G14: 28688733 | H14: 0.1532
A15: 1 | B15: Mobiles & Accessories | C15: 2021-12 | D15: 2021 | E15: 12 | F15: 30883593 | G15: 26252193 | H15: 0.15
... A963: 20 | B963: Festive & Gifting | C963: 2024-12 | D963: 2024 | E963: 12 | F963: 7952461 | G963: 4844544.5 | H963: 0.3908

Sheet 01_Model_Promotion
A1: 01_Model_Promotion — ETL output (materialized). Source: Power Query joins documented in PowerQuery_DAX_Specification.md
A3: promotion_id | B3: revenue | C3: cost | D3: orders | E3: lines | F3: margin | G3: margin_pct | H3: avg_order_value | I3: promotion_name | J3: promotion_type | K3: discount_pct | L3: start_date | M3: end_date | N3: baseline_margin_pct | O3: baseline_avg_order_value | P3: margin_pct_delta_pp | Q3: aov_lift_pct
A4: 158 | B4: 478598231 | C4: 3.9289352e+08 | D4: 6171 | E4: 13564 | F4: 85704709 | G4: 0.1791 | H4: 77556.03 | I4: Loyalty Sep2024 - 5% Off | J4: Loyalty | K4: 5 | L4: 2024-09-19 | M4: 2024-10-03 | N4: 0.2226 | O4: 68093.63 | P4: -0.0435 | Q4: 0.139
A5: 182 | B5: 265770437 | C5: 2.1793244e+08 | D5: 3447 | E5: 7559 | F5: 47837999 | G5: 0.18 | H5: 77101.95 | I5: Festive Nov2024 - 5% Off | J5: Festive | K5: 5 | L5: 2024-11-26 | M5: 2024-12-06 | N5: 0.2226 | O5: 68093.63 | P5: -0.0426 | Q5: 0.1323
A6: 104 | B6: 261412791 | C6: 2.1400298e+08 | D6: 3408 | E6: 7433 | F6: 47409807 | G6: 0.1814 | H6: 76705.63 | I6: Seasonal Nov2024 - 5% Off | J6: Seasonal | K6: 5 | L6: 2024-11-24 | M6: 2024-12-01 | N6: 0.2226 | O6: 68093.63 | P6: -0.0413 | Q6: 0.1265
A7: 191 | B7: 171291786 | C7: 1.5652976e+08 | D7: 2409 | E7: 5330 | F7: 14762024 | G7: 0.0862 | H7: 71104.93 | I7: Seasonal Dec2023 - 15% Off | J7: Seasonal | K7: 15 | L7: 2023-12-25 | M7: 2024-01-12 | N7: 0.2226 | O7: 68093.63 | P7: -0.1364 | Q7: 0.0442
A8: 86 | B8: 150307327 | C8: 1.2305607e+08 | D8: 1902 | E8: 4193 | F8: 27251254 | G8: 0.1813 | H8: 79025.93 | I8: Festive Nov2022 - 5% Off | J8: Festive | K8: 5 | L8: 2022-11-27 | M8: 2022-12-17 | N8: 0.2226 | O8: 68093.63 | P8: -0.0413 | Q8: 0.1605
A9: 37 | B9: 136643946 | C9: 1.1178656e+08 | D9: 1852 | E9: 4016 | F9: 24857382 | G9: 0.1819 | H9: 73781.83 | I9: Festive Oct2021 - 5% Off | J9: Festive | K9: 5 | L9: 2021-10-30 | M9: 2021-11-06 | N9: 0.2226 | O9: 68093.63 | P9: -0.0407 | Q9: 0.0835
A10: 72 | B10: 132548651 | C10: 1.1432939e+08 | D10: 1875 | E10: 4059 | F10: 18219261 | G10: 0.1375 | H10: 70692.61 | I10: Festive Jun2022 - 10% Off | J10: Festive | K10: 10 | L10: 2022-06-27 | M10: 2022-07-09 | N10: 0.2226 | O10: 68093.63 | P10: -0.0852 | Q10: 0.0382
A11: 187 | B11: 130796895 | C11: 1.3550542e+08 | D11: 2219 | E11: 4843 | F11: -4708521.8 | G11: -0.036 | H11: 58944.07 | I11: Festive Nov2023 - 25% Off | J11: Festive | K11: 25 | L11: 2023-11-27 | M11: 2023-12-13 | N11: 0.2226 | O11: 68093.63 | P11: -0.2586 | Q11: -0.1344
A12: 155 | B12: 130476222 | C12: 1.1545389e+08 | D12: 1895 | E12: 4194 | F12: 15022331 | G12: 0.1151 | H12: 68852.89 | I12: Seasonal Nov2022 - 12% Off | J12: Seasonal | K12: 12 | L12: 2022-11-22 | M12: 2022-12-04 | N12: 0.2226 | O12: 68093.63 | P12: -0.1075 | Q12: 0.0112
A13: 140 | B13: 127756385 | C13: 1.1743837e+08 | D13: 1818 | E13: 3952 | F13: 10318013 | G13: 0.0808 | H13: 70273.04 | I13: Festive Oct2021 - 15% Off | J13: Festive | K13: 15 | L13: 2021-10-26 | M13: 2021-11-07 | N13: 0.2226 | O13: 68093.63 | P13: -0.1419 | Q13: 0.032
A14: 60 | B14: 124049338 | C14: 1.3775341e+08 | D14: 2238 | E14: 4985 | F14: -13704073 | G14: -0.1105 | H14: 55428.66 | I14: Loyalty Nov2023 - 30% Off | J14: Loyalty | K14: 30 | L14: 2023-11-13 | M14: 2023-12-01 | N14: 0.2226 | O14: 68093.63 | P14: -0.3331 | Q14: -0.186
A15: 83 | B15: 111883993 | C15: 1.2445211e+08 | D15: 1945 | E15: 4312 | F15: -12568118 | G15: -0.1123 | H15: 57523.9 | I15: Flash Sale Jun2022 - 30% Off | J15: Flash Sale | K15: 30 | L15: 2022-06-30 | M15: 2022-07-02 | N15: 0.2226 | O15: 68093.63 | P15: -0.335 | Q15: -0.1552
... A203: 193 | B203: 10199470 | C203: 10693015 | D203: 190 | E203: 391 | F203: -493544.72 | G203: -0.0484 | H203: 53681.42 | I203: Loyalty Jun2021 - 25% Off | J203: Loyalty | K203: 25 | L203: 2021-06-19 | M203: 2021-06-28 | N203: 0.2226 | O203: 68093.63 | P203: -0.271 | Q203: -0.2117

Sheet 01_Model_SLA
A1: 01_Model_SLA — ETL output (materialized). Source: Power Query joins documented in PowerQuery_DAX_Specification.md
A3: region_id | B3: region_name | C3: courier_partner | D3: shipment_count | E3: late_count | F3: late_rate
A4: 1 | B4: Delhi NCR | C4: BlueDart Express | D4: 3842 | E4: 337 | F4: 0.0877
A5: 1 | B5: Delhi NCR | C5: DTDC | D5: 3886 | E5: 342 | F5: 0.088
A6: 1 | B6: Delhi NCR | C6: Delhivery | D6: 3889 | E6: 307 | F6: 0.0789
A7: 1 | B7: Delhi NCR | C7: Ekart Logistics | D7: 3868 | E7: 320 | F7: 0.0827
A8: 1 | B8: Delhi NCR | C8: XpressBees | D8: 4017 | E8: 311 | F8: 0.0774
A9: 4 | B9: Gujarat | C9: BlueDart Express | D9: 4142 | E9: 388 | F9: 0.0937
A10: 4 | B10: Gujarat | C10: DTDC | D10: 4009 | E10: 385 | F10: 0.096
A11: 4 | B11: Gujarat | C11: Delhivery | D11: 4153 | E11: 404 | F11: 0.0973
A12: 4 | B12: Gujarat | C12: Ekart Logistics | D12: 4172 | E12: 408 | F12: 0.0978
A13: 4 | B13: Gujarat | C13: XpressBees | D13: 3986 | E13: 382 | F13: 0.0958
A14: 5 | B14: Karnataka | C14: BlueDart Express | D14: 5349 | E14: 541 | F14: 0.1011
A15: 5 | B15: Karnataka | C15: DTDC | D15: 5425 | E15: 525 | F15: 0.0968
... A63: 9 | B63: West Bengal | C63: XpressBees | D63: 8038 | E63: 743 | F63: 0.0924

Sheet 02_KPI_Margin
A1: Q1 — Revenue & Margin Trend
A2: All figures computed live from 01_Model_Overall_Month. No typed totals.
A4: Overall Metrics (Full Period: Jan 2021 - Dec 2024)
A5: Total Revenue | B5: =SUM(tblModelOverallMonth[revenue]) -> 18879364487
A6: Total Cost | B6: =SUM(tblModelOverallMonth[cost]) -> 1.6237586e+10
A7: Total Margin (Rs) | B7: =B5-B6 -> 2.6417786e+09
A8: Overall Margin % | B8: =B7/B5 -> 0.13992943
A9: Margin % Volatility (StDev of monthly margin %) | B9: =STDEV(tblModelOverallMonth[margin_pct]) -> 0.026464573
A10: Highest Monthly Margin % | B10: =MAX(tblModelOverallMonth[margin_pct]) -> 0.199
A11: Lowest Monthly Margin % | B11: =MIN(tblModelOverallMonth[margin_pct]) -> 0.059
A12: Margin % Range (Volatility Spread) | B12: =B10-B11 -> 0.14
A14: Margin % by Year
A15: Year | B15: Revenue | C15: Cost | D15: Margin | E15: Margin %
A16: 2021 | B16: =SUMIFS(tblModelOverallMonth[revenue],tblModelOverallMonth[year],A16) -> 3032246133 | C16: =SUMIFS(tblModelOverallMonth[cost],tblModelOverallMonth[year],A16) -> 2.6049533e+09 | D16: =B16-C16 -> 4.2729282e+08 | E16: =D16/B16 -> 0.14091627
A17: 2022 | B17: =SUMIFS(tblModelOverallMonth[revenue],tblModelOverallMonth[year],A17) -> 4288277586 | C17: =SUMIFS(tblModelOverallMonth[cost],tblModelOverallMonth[year],A17) -> 3.7151179e+09 | D17: =B17-C17 -> 5.7315965e+08 | E17: =D17/B17 -> 0.13365731
A18: 2023 | B18: =SUMIFS(tblModelOverallMonth[revenue],tblModelOverallMonth[year],A18) -> 5394885335 | C18: =SUMIFS(tblModelOverallMonth[cost],tblModelOverallMonth[year],A18) -> 4.7347705e+09 | D18: =B18-C18 -> 6.6011484e+08 | E18: =D18/B18 -> 0.12235938
A19: 2024 | B19: =SUMIFS(tblModelOverallMonth[revenue],tblModelOverallMonth[year],A19) -> 6163955433 | C19: =SUMIFS(tblModelOverallMonth[cost],tblModelOverallMonth[year],A19) -> 5.1827441e+09 | D19: =B19-C19 -> 9.8121134e+08 | E19: =D19/B19 -> 0.15918534
A22: Last 6 Months (Jul-Dec 2024) vs Prior 6 Months (Jan-Jun 2024)
A23: Period | B23: Revenue | C23: Margin %
A24: Prior 6M (Jan-Jun 2024) | B24: =SUMIFS(tblModelOverallMonth[revenue],tblModelOverallMonth[year],2024,tblModelOverallMonth[month],">=1",tblModelOverallMonth[month],"<=6") -> 2629402466 | C24: =SUMIFS(tblModelOverallMonth[margin],tblModelOverallMonth[year],2024,tblModelOverallMonth[month],">=1",tblModelOverallMonth[month],"<=6")/B24 -> 0.13710958
A25: Last 6M (Jul-Dec 2024) | B25: =SUMIFS(tblModelOverallMonth[revenue],tblModelOverallMonth[year],2024,tblModelOverallMonth[month],">=7",tblModelOverallMonth[month],"<=12") -> 3534552967 | C25: =SUMIFS(tblModelOverallMonth[margin],tblModelOverallMonth[year],2024,tblModelOverallMonth[month],">=7",tblModelOverallMonth[month],"<=12")/B25 -> 0.1756078
A26: Change (percentage points) | C26: =C25-C24 -> 0.03849822

Sheet 03_KPI_Target
A1: Q2 — Target vs Achievement (Region-Level; no store-level target exists in source data)
A3: FY2024 Region-Level Target vs Achievement (Jan-Dec 2024)
A4: Region | B4: Zone | C4: Revenue 2024 | D4: Target 2024 | E4: Achievement % | F4: Status
A5: Delhi NCR | B5: North | C5: =SUMIFS(tblModelRegionMonth[revenue],tblModelRegionMonth[region_name],A5,tblModelRegionMonth[year],2024) -> 427064177 | D5: =SUMIFS(tblModelRegionMonth[target_amount],tblModelRegionMonth[region_name],A5,tblModelRegionMonth[year],2024) -> 372579000 | E5: =C5/D5 -> 1.1462379 | F5: =IF(E5>=1,"On/Above Target","Below Target") -> On/Above Target
A6: Gujarat | B6: West | C6: =SUMIFS(tblModelRegionMonth[revenue],tblModelRegionMonth[region_name],A6,tblModelRegionMonth[year],2024) -> 450052766 | D6: =SUMIFS(tblModelRegionMonth[target_amount],tblModelRegionMonth[region_name],A6,tblModelRegionMonth[year],2024) -> 415613000 | E6: =C6/D6 -> 1.082865 | F6: =IF(E6>=1,"On/Above Target","Below Target") -> On/Above Target
A7: Karnataka | B7: South | C7: =SUMIFS(tblModelRegionMonth[revenue],tblModelRegionMonth[region_name],A7,tblModelRegionMonth[year],2024) -> 591917328 | D7: =SUMIFS(tblModelRegionMonth[target_amount],tblModelRegionMonth[region_name],A7,tblModelRegionMonth[year],2024) -> 544739000 | E7: =C7/D7 -> 1.0866072 | F7: =IF(E7>=1,"On/Above Target","Below Target") -> On/Above Target
A8: Kerala | B8: South | C8: =SUMIFS(tblModelRegionMonth[revenue],tblModelRegionMonth[region_name],A8,tblModelRegionMonth[year],2024) -> 427842945 | D8: =SUMIFS(tblModelRegionMonth[target_amount],tblModelRegionMonth[region_name],A8,tblModelRegionMonth[year],2024) -> 338539000 | E8: =C8/D8 -> 1.2637922 | F8: =IF(E8>=1,"On/Above Target","Below Target") -> On/Above Target
A9: Madhya Pradesh | B9: Central | C9: =SUMIFS(tblModelRegionMonth[revenue],tblModelRegionMonth[region_name],A9,tblModelRegionMonth[year],2024) -> 334767166 | D9: =SUMIFS(tblModelRegionMonth[target_amount],tblModelRegionMonth[region_name],A9,tblModelRegionMonth[year],2024) -> 270092000 | E9: =C9/D9 -> 1.2394561 | F9: =IF(E9>=1,"On/Above Target","Below Target") -> On/Above Target
A10: Maharashtra | B10: West | C10: =SUMIFS(tblModelRegionMonth[revenue],tblModelRegionMonth[region_name],A10,tblModelRegionMonth[year],2024) -> 606425965 | D10: =SUMIFS(tblModelRegionMonth[target_amount],tblModelRegionMonth[region_name],A10,tblModelRegionMonth[year],2024) -> 554212000 | E10: =C10/D10 -> 1.094213 | F10: =IF(E10>=1,"On/Above Target","Below Target") -> On/Above Target
A11: Odisha-Jharkhand | B11: East | C11: =SUMIFS(tblModelRegionMonth[revenue],tblModelRegionMonth[region_name],A11,tblModelRegionMonth[year],2024) -> 333544565 | D11: =SUMIFS(tblModelRegionMonth[target_amount],tblModelRegionMonth[region_name],A11,tblModelRegionMonth[year],2024) -> 341602000 | E11: =C11/D11 -> 0.9764128 | F11: =IF(E11>=1,"On/Above Target","Below Target") -> Below Target
A12: Punjab-Haryana | B12: North | C12: =SUMIFS(tblModelRegionMonth[revenue],tblModelRegionMonth[region_name],A12,tblModelRegionMonth[year],2024) -> 743332896 | D12: =SUMIFS(tblModelRegionMonth[target_amount],tblModelRegionMonth[region_name],A12,tblModelRegionMonth[year],2024) -> 693045000 | E12: =C12/D12 -> 1.0725608 | F12: =IF(E12>=1,"On/Above Target","Below Target") -> On/Above Target
A13: Rajasthan | B13: North | C13: =SUMIFS(tblModelRegionMonth[revenue],tblModelRegionMonth[region_name],A13,tblModelRegionMonth[year],2024) -> 459325321 | D13: =SUMIFS(tblModelRegionMonth[target_amount],tblModelRegionMonth[region_name],A13,tblModelRegionMonth[year],2024) -> 391442000 | E13: =C13/D13 -> 1.1734186 | F13: =IF(E13>=1,"On/Above Target","Below Target") -> On/Above Target
A14: Tamil Nadu | B14: South | C14: =SUMIFS(tblModelRegionMonth[revenue],tblModelRegionMonth[region_name],A14,tblModelRegionMonth[year],2024) -> 614337984 | D14: =SUMIFS(tblModelRegionMonth[target_amount],tblModelRegionMonth[region_name],A14,tblModelRegionMonth[year],2024) -> 617125000 | E14: =C14/D14 -> 0.99548387 | F14: =IF(E14>=1,"On/Above Target","Below Target") -> Below Target
A15: Telangana-AP | B15: South | C15: =SUMIFS(tblModelRegionMonth[revenue],tblModelRegionMonth[region_name],A15,tblModelRegionMonth[year],2024) -> 275671560 | D15: =SUMIFS(tblModelRegionMonth[target_amount],tblModelRegionMonth[region_name],A15,tblModelRegionMonth[year],2024) -> 284519000 | E15: =C15/D15 -> 0.96890387 | F15: =IF(E15>=1,"On/Above Target","Below Target") -> Below Target
A16: West Bengal | B16: East | C16: =SUMIFS(tblModelRegionMonth[revenue],tblModelRegionMonth[region_name],A16,tblModelRegionMonth[year],2024) -> 899672760 | D16: =SUMIFS(tblModelRegionMonth[target_amount],tblModelRegionMonth[region_name],A16,tblModelRegionMonth[year],2024) -> 763106000 | E16: =C16/D16 -> 1.1789617 | F16: =IF(E16>=1,"On/Above Target","Below Target") -> On/Above Target

Sheet 04_KPI_Category
A1: Q3 — Which categories drive revenue but not profit, and why | H1: Overall Avg Margin % | I1: =AVERAGE(tblModelCategory[margin_pct]) -> 0.23779
A2: Ranked by revenue. Diagnostic columns show discount leakage % and return rate as candidate causes. | H2: Median Revenue Share % | I2: =MEDIAN(C5:C24) -> 0.012622715
A4: Category | B4: Revenue | C4: Revenue Share % | D4: Margin % | E4: Discount Leak % | F4: Return Rate % | G4: Diagnosis
A5: =INDEX(tblModelCategory[category_name],1) -> Refrigerators | B5: =INDEX(tblModelCategory[revenue],1) -> 4382590644 | C5: =B5/SUM(tblModelCategory[revenue]) -> 0.23213656 | D5: =INDEX(tblModelCategory[margin_pct],1) -> 0.1217 | E5: =INDEX(tblModelCategory[discount_leak_pct],1) -> 0.0985 | F5: =INDEX(tblModelCategory[return_rate],1) -> 0.0355 | G5: =IF(AND(C5>$I$2,D5<$I$1),"High Revenue / Low Margin - review discount & returns",IF(AND(C5>$I$2,D5>=$I$1),"High Revenue / Healthy Margin",IF(AND(C5<=$I$2,D5<$I$1),"Low Revenue / Low Margin - low priority","Low Revenue / Healthy Margin"))) -> High Revenue / Low Margin - review discount & returns
A6: =INDEX(tblModelCategory[category_name],2) -> Laptops & Computers | B6: =INDEX(tblModelCategory[revenue],2) -> 2977044772 | C6: =B6/SUM(tblModelCategory[revenue]) -> 0.15768776 | D6: =INDEX(tblModelCategory[margin_pct],2) -> 0.0572 | E6: =INDEX(tblModelCategory[discount_leak_pct],2) -> 0.0994 | F6: =INDEX(tblModelCategory[return_rate],2) -> 0.0465 | G6: =IF(AND(C6>$I$2,D6<$I$1),"High Revenue / Low Margin - review discount & returns",IF(AND(C6>$I$2,D6>=$I$1),"High Revenue / Healthy Margin",IF(AND(C6<=$I$2,D6<$I$1),"Low Revenue / Low Margin - low priority","Low Revenue / Healthy Margin"))) -> High Revenue / Low Margin - review discount & returns
A7: =INDEX(tblModelCategory[category_name],3) -> Televisions | B7: =INDEX(tblModelCategory[revenue],3) -> 2296118310 | C7: =B7/SUM(tblModelCategory[revenue]) -> 0.12162053 | D7: =INDEX(tblModelCategory[margin_pct],3) -> 0.1195 | E7: =INDEX(tblModelCategory[discount_leak_pct],3) -> 0.0986 | F7: =INDEX(tblModelCategory[return_rate],3) -> 0.0414 | G7: =IF(AND(C7>$I$2,D7<$I$1),"High Revenue / Low Margin - review discount & returns",IF(AND(C7>$I$2,D7>=$I$1),"High Revenue / Healthy Margin",IF(AND(C7<=$I$2,D7<$I$1),"Low Revenue / Low Margin - low priority","Low Revenue / Healthy Margin"))) -> High Revenue / Low Margin - review discount & returns
A8: =INDEX(tblModelCategory[category_name],4) -> Furniture | B8: =INDEX(tblModelCategory[revenue],4) -> 1907350207 | C8: =B8/SUM(tblModelCategory[revenue]) -> 0.10102831 | D8: =INDEX(tblModelCategory[margin_pct],4) -> 0.1605 | E8: =INDEX(tblModelCategory[discount_leak_pct],4) -> 0.0993 | F8: =INDEX(tblModelCategory[return_rate],4) -> 0.0313 | G8: =IF(AND(C8>$I$2,D8<$I$1),"High Revenue / Low Margin - review discount & returns",IF(AND(C8>$I$2,D8>=$I$1),"High Revenue / Healthy Margin",IF(AND(C8<=$I$2,D8<$I$1),"Low Revenue / Low Margin - low priority","Low Revenue / Healthy Margin"))) -> High Revenue / Low Margin - review discount & returns
A9: =INDEX(tblModelCategory[category_name],5) -> Mobiles & Accessories | B9: =INDEX(tblModelCategory[revenue],5) -> 1718375549 | C9: =B9/SUM(tblModelCategory[revenue]) -> 0.091018718 | D9: =INDEX(tblModelCategory[margin_pct],5) -> 0.1198 | E9: =INDEX(tblModelCategory[discount_leak_pct],5) -> 0.0983 | F9: =INDEX(tblModelCategory[return_rate],5) -> 0.0435 | G9: =IF(AND(C9>$I$2,D9<$I$1),"High Revenue / Low Margin - review discount & returns",IF(AND(C9>$I$2,D9>=$I$1),"High Revenue / Healthy Margin",IF(AND(C9<=$I$2,D9<$I$1),"Low Revenue / Low Margin - low priority","Low Revenue / Healthy Margin"))) -> High Revenue / Low Margin - review discount & returns
A10: =INDEX(tblModelCategory[category_name],6) -> Air Conditioners & Coolers | B10: =INDEX(tblModelCategory[revenue],6) -> 1462422495 | C10: =B10/SUM(tblModelCategory[revenue]) -> 0.077461426 | D10: =INDEX(tblModelCategory[margin_pct],6) -> 0.1046 | E10: =INDEX(tblModelCategory[discount_leak_pct],6) -> 0.0999 | F10: =INDEX(tblModelCategory[return_rate],6) -> 0.036 | G10: =IF(AND(C10>$I$2,D10<$I$1),"High Revenue / Low Margin - review discount & returns",IF(AND(C10>$I$2,D10>=$I$1),"High Revenue / Healthy Margin",IF(AND(C10<=$I$2,D10<$I$1),"Low Revenue / Low Margin - low priority","Low Revenue / Healthy Margin"))) -> High Revenue / Low Margin - review discount & returns
A11: =INDEX(tblModelCategory[category_name],7) -> Washing Machines | B11: =INDEX(tblModelCategory[revenue],7) -> 1242288851 | C11: =B11/SUM(tblModelCategory[revenue]) -> 0.065801413 | D11: =INDEX(tblModelCategory[margin_pct],7) -> 0.1156 | E11: =INDEX(tblModelCategory[discount_leak_pct],7) -> 0.0981 | F11: =INDEX(tblModelCategory[return_rate],7) -> 0.034 | G11: =IF(AND(C11>$I$2,D11<$I$1),"High Revenue / Low Margin - review discount & returns",IF(AND(C11>$I$2,D11>=$I$1),"High Revenue / Healthy Margin",IF(AND(C11<=$I$2,D11<$I$1),"Low Revenue / Low Margin - low priority","Low Revenue / Healthy Margin"))) -> High Revenue / Low Margin - review discount & returns
A12: =INDEX(tblModelCategory[category_name],8) -> Kitchen Appliances | B12: =INDEX(tblModelCategory[revenue],8) -> 602723939 | C12: =B12/SUM(tblModelCategory[revenue]) -> 0.031925012 | D12: =INDEX(tblModelCategory[margin_pct],8) -> 0.2781 | E12: =INDEX(tblModelCategory[discount_leak_pct],8) -> 0.0986 | F12: =INDEX(tblModelCategory[return_rate],8) -> 0.0286 | G12: =IF(AND(C12>$I$2,D12<$I$1),"High Revenue / Low Margin - review discount & returns",IF(AND(C12>$I$2,D12>=$I$1),"High Revenue / Healthy Margin",IF(AND(C12<=$I$2,D12<$I$1),"Low Revenue / Low Margin - low priority","Low Revenue / Healthy Margin"))) -> High Revenue / Healthy Margin
A13: =INDEX(tblModelCategory[category_name],9) -> Home Audio | B13: =INDEX(tblModelCategory[revenue],9) -> 520527346 | C13: =B13/SUM(tblModelCategory[revenue]) -> 0.027571232 | D13: =INDEX(tblModelCategory[margin_pct],9) -> 0.1863 | E13: =INDEX(tblModelCategory[discount_leak_pct],9) -> 0.0988 | F13: =INDEX(tblModelCategory[return_rate],9) -> 0.0387 | G13: =IF(AND(C13>$I$2,D13<$I$1),"High Revenue / Low Margin - review discount & returns",IF(AND(C13>$I$2,D13>=$I$1),"High Revenue / Healthy Margin",IF(AND(C13<=$I$2,D13<$I$1),"Low Revenue / Low Margin - low priority","Low Revenue / Healthy Margin"))) -> High Revenue / Low Margin - review discount & returns
A14: =INDEX(tblModelCategory[category_name],10) -> Heaters & Winter Appliances | B14: =INDEX(tblModelCategory[revenue],10) -> 258134495 | C14: =B14/SUM(tblModelCategory[revenue]) -> 0.013672838 | D14: =INDEX(tblModelCategory[margin_pct],10) -> 0.26 | E14: =INDEX(tblModelCategory[discount_leak_pct],10) -> 0.0983 | F14: =INDEX(tblModelCategory[return_rate],10) -> 0.0268 | G14: =IF(AND(C14>$I$2,D14<$I$1),"High Revenue / Low Margin - review discount & returns",IF(AND(C14>$I$2,D14>=$I$1),"High Revenue / Healthy Margin",IF(AND(C14<=$I$2,D14<$I$1),"Low Revenue / Low Margin - low priority","Low Revenue / Healthy Margin"))) -> High Revenue / Healthy Margin
A15: =INDEX(tblModelCategory[category_name],11) -> Footwear | B15: =INDEX(tblModelCategory[revenue],11) -> 218483178 | C15: =B15/SUM(tblModelCategory[revenue]) -> 0.011572592 | D15: =INDEX(tblModelCategory[margin_pct],11) -> 0.3335 | E15: =INDEX(tblModelCategory[discount_leak_pct],11) -> 0.0993 | F15: =INDEX(tblModelCategory[return_rate],11) -> 0.0676 | G15: =IF(AND(C15>$I$2,D15<$I$1),"High Revenue / Low Margin - review discount & returns",IF(AND(C15>$I$2,D15>=$I$1),"High Revenue / Healthy Margin",IF(AND(C15<=$I$2,D15<$I$1),"Low Revenue / Low Margin - low priority","Low Revenue / Healthy Margin"))) -> Low Revenue / Healthy Margin
A16: =INDEX(tblModelCategory[category_name],12) -> Festive & Gifting | B16: =INDEX(tblModelCategory[revenue],12) -> 216122731 | C16: =B16/SUM(tblModelCategory[revenue]) -> 0.011447564 | D16: =INDEX(tblModelCategory[margin_pct],12) -> 0.3476 | E16: =INDEX(tblModelCategory[discount_leak_pct],12) -> 0.0986 | F16: =INDEX(tblModelCategory[return_rate],12) -> 0.0299 | G16: =IF(AND(C16>$I$2,D16<$I$1),"High Revenue / Low Margin - review discount & returns",IF(AND(C16>$I$2,D16>=$I$1),"High Revenue / Healthy Margin",IF(AND(C16<=$I$2,D16<$I$1),"Low Revenue / Low Margin - low priority","Low Revenue / Healthy Margin"))) -> Low Revenue / Healthy Margin
A17: =INDEX(tblModelCategory[category_name],13) -> Home Decor | B17: =INDEX(tblModelCategory[revenue],13) -> 190662742 | C17: =B17/SUM(tblModelCategory[revenue]) -> 0.010099002 | D17: =INDEX(tblModelCategory[margin_pct],13) -> 0.3881 | E17: =INDEX(tblModelCategory[discount_leak_pct],13) -> 0.0978 | F17: =INDEX(tblModelCategory[return_rate],13) -> 0.0288 | G17: =IF(AND(C17>$I$2,D17<$I$1),"High Revenue / Low Margin - review discount & returns",IF(AND(C17>$I$2,D17>=$I$1),"High Revenue / Healthy Margin",IF(AND(C17<=$I$2,D17<$I$1),"Low Revenue / Low Margin - low priority","Low Revenue / Healthy Margin"))) -> Low Revenue / Healthy Margin
A18: =INDEX(tblModelCategory[category_name],14) -> Women's Apparel | B18: =INDEX(tblModelCategory[revenue],14) -> 180387906 | C18: =B18/SUM(tblModelCategory[revenue]) -> 0.0095547658 | D18: =INDEX(tblModelCategory[margin_pct],14) -> 0.4008 | E18: =INDEX(tblModelCategory[discount_leak_pct],14) -> 0.0989 | F18: =INDEX(tblModelCategory[return_rate],14) -> 0.0672 | G18: =IF(AND(C18>$I$2,D18<$I$1),"High Revenue / Low Margin - review discount & returns",IF(AND(C18>$I$2,D18>=$I$1),"High Revenue / Healthy Margin",IF(AND(C18<=$I$2,D18<$I$1),"Low Revenue / Low Margin - low priority","Low Revenue / Healthy Margin"))) -> Low Revenue / Healthy Margin
A19: =INDEX(tblModelCategory[category_name],15) -> Men's Apparel | B19: =INDEX(tblModelCategory[revenue],15) -> 174253220 | C19: =B19/SUM(tblModelCategory[revenue]) -> 0.0092298245 | D19: =INDEX(tblModelCategory[margin_pct],15) -> 0.3818 | E19: =INDEX(tblModelCategory[discount_leak_pct],15) -> 0.0973 | F19: =INDEX(tblModelCategory[return_rate],15) -> 0.0693 | G19: =IF(AND(C19>$I$2,D19<$I$1),"High Revenue / Low Margin - review discount & returns",IF(AND(C19>$I$2,D19>=$I$1),"High Revenue / Healthy Margin",IF(AND(C19<=$I$2,D19<$I$1),"Low Revenue / Low Margin - low priority","Low Revenue / Healthy Margin"))) -> Low Revenue / Healthy Margin
A20: =INDEX(tblModelCategory[category_name],16) -> Toys & Games | B20: =INDEX(tblModelCategory[revenue],16) -> 152264378 | C20: =B20/SUM(tblModelCategory[revenue]) -> 0.008065122 | D20: =INDEX(tblModelCategory[margin_pct],16) -> 0.2979 | E20: =INDEX(tblModelCategory[discount_leak_pct],16) -> 0.0989 | F20: =INDEX(tblModelCategory[return_rate],16) -> 0.0314 | G20: =IF(AND(C20>$I$2,D20<$I$1),"High Revenue / Low Margin - review discount & returns",IF(AND(C20>$I$2,D20>=$I$1),"High Revenue / Healthy Margin",IF(AND(C20<=$I$2,D20<$I$1),"Low Revenue / Low Margin - low priority","Low Revenue / Healthy Margin"))) -> Low Revenue / Healthy Margin
A21: =INDEX(tblModelCategory[category_name],17) -> Kitchenware | B21: =INDEX(tblModelCategory[revenue],17) -> 150573007 | C21: =B21/SUM(tblModelCategory[revenue]) -> 0.0079755337 | D21: =INDEX(tblModelCategory[margin_pct],17) -> 0.3423 | E21: =INDEX(tblModelCategory[discount_leak_pct],17) -> 0.1008 | F21: =INDEX(tblModelCategory[return_rate],17) -> 0.0262 | G21: =IF(AND(C21>$I$2,D21<$I$1),"High Revenue / Low Margin - review discount & returns",IF(AND(C21>$I$2,D21>=$I$1),"High Revenue / Healthy Margin",IF(AND(C21<=$I$2,D21<$I$1),"Low Revenue / Low Margin - low priority","Low Revenue / Healthy Margin"))) -> Low Revenue / Healthy Margin
A22: =INDEX(tblModelCategory[category_name],18) -> Kids Apparel | B22: =INDEX(tblModelCategory[revenue],18) -> 109354906 | C22: =B22/SUM(tblModelCategory[revenue]) -> 0.005792298 | D22: =INDEX(tblModelCategory[margin_pct],18) -> 0.3757 | E22: =INDEX(tblModelCategory[discount_leak_pct],18) -> 0.101 | F22: =INDEX(tblModelCategory[return_rate],18) -> 0.0692 | G22: =IF(AND(C22>$I$2,D22<$I$1),"High Revenue / Low Margin - review discount & returns",IF(AND(C22>$I$2,D22>=$I$1),"High Revenue / Healthy Margin",IF(AND(C22<=$I$2,D22<$I$1),"Low Revenue / Low Margin - low priority","Low Revenue / Healthy Margin"))) -> Low Revenue / Healthy Margin
A23: =INDEX(tblModelCategory[category_name],19) -> Personal Care | B23: =INDEX(tblModelCategory[revenue],19) -> 74610385 | C23: =B23/SUM(tblModelCategory[revenue]) -> 0.0039519543 | D23: =INDEX(tblModelCategory[margin_pct],19) -> 0.2769 | E23: =INDEX(tblModelCategory[discount_leak_pct],19) -> 0.0999 | F23: =INDEX(tblModelCategory[return_rate],19) -> 0.0076 | G23: =IF(AND(C23>$I$2,D23<$I$1),"High Revenue / Low Margin - review discount & returns",IF(AND(C23>$I$2,D23>=$I$1),"High Revenue / Healthy Margin",IF(AND(C23<=$I$2,D23<$I$1),"Low Revenue / Low Margin - low priority","Low Revenue / Healthy Margin"))) -> Low Revenue / Healthy Margin
A24: =INDEX(tblModelCategory[category_name],20) -> Groceries & Staples | B24: =INDEX(tblModelCategory[revenue],20) -> 45075426 | C24: =B24/SUM(tblModelCategory[revenue]) -> 0.00238755 | D24: =INDEX(tblModelCategory[margin_pct],20) -> 0.0879 | E24: =INDEX(tblModelCategory[discount_leak_pct],20) -> 0.0992 | F24: =INDEX(tblModelCategory[return_rate],20) -> 0.0075 | G24: =IF(AND(C24>$I$2,D24<$I$1),"High Revenue / Low Margin - review discount & returns",IF(AND(C24>$I$2,D24>=$I$1),"High Revenue / Healthy Margin",IF(AND(C24<=$I$2,D24<$I$1),"Low Revenue / Low Margin - low priority","Low Revenue / Healthy Margin"))) -> Low Revenue / Low Margin - low priority

Sheet 05_KPI_Discount
A1: Q5 — Where discounting erodes margin the most | H1: Overall Avg Discount Leak % | I1: =AVERAGE(tblModelCategory[discount_leak_pct]) -> 0.098975
A2: Category-level discount leakage (catalog price vs actual charged price). Flagged vs overall average.
A4: Category | B4: Revenue | C4: Catalog Value | D4: Discount Leakage (Rs) | E4: Discount Leakage % | F4: Flag
A5: =INDEX(tblModelCategory[category_name],MATCH("Kids Apparel",tblModelCategory[category_name],0)) -> Kids Apparel | B5: =SUMIFS(tblModelCategory[revenue],tblModelCategory[category_name],A5) -> 109354906 | C5: =SUMIFS(tblModelCategory[catalog_value],tblModelCategory[category_name],A5) -> 121236720 | D5: =SUMIFS(tblModelCategory[discount_leak],tblModelCategory[category_name],A5) -> 12241067 | E5: =D5/C5 -> 0.10096831 | F5: =IF(E5>$I$1,"Above Average - Review Discount Policy","Within Normal Range") -> Above Average - Review Discount Policy
A6: =INDEX(tblModelCategory[category_name],MATCH("Kitchenware",tblModelCategory[category_name],0)) -> Kitchenware | B6: =SUMIFS(tblModelCategory[revenue],tblModelCategory[category_name],A6) -> 150573007 | C6: =SUMIFS(tblModelCategory[catalog_value],tblModelCategory[category_name],A6) -> 166904040 | D6: =SUMIFS(tblModelCategory[discount_leak],tblModelCategory[category_name],A6) -> 16830249 | E6: =D6/C6 -> 0.10083788 | F6: =IF(E6>$I$1,"Above Average - Review Discount Policy","Within Normal Range") -> Above Average - Review Discount Policy
A7: =INDEX(tblModelCategory[category_name],MATCH("Personal Care",tblModelCategory[category_name],0)) -> Personal Care | B7: =SUMIFS(tblModelCategory[revenue],tblModelCategory[category_name],A7) -> 74610385 | C7: =SUMIFS(tblModelCategory[catalog_value],tblModelCategory[category_name],A7) -> 82606690 | D7: =SUMIFS(tblModelCategory[discount_leak],tblModelCategory[category_name],A7) -> 8249305 | E7: =D7/C7 -> 0.099862432 | F7: =IF(E7>$I$1,"Above Average - Review Discount Policy","Within Normal Range") -> Above Average - Review Discount Policy
A8: =INDEX(tblModelCategory[category_name],MATCH("Air Conditioners & Coolers",tblModelCategory[category_name],0)) -> Air Conditioners & Coolers | B8: =SUMIFS(tblModelCategory[revenue],tblModelCategory[category_name],A8) -> 1462422495 | C8: =SUMIFS(tblModelCategory[catalog_value],tblModelCategory[category_name],A8) -> 1619237220 | D8: =SUMIFS(tblModelCategory[discount_leak],tblModelCategory[category_name],A8) -> 161801886 | E8: =D8/C8 -> 0.099924757 | F8: =IF(E8>$I$1,"Above Average - Review Discount Policy","Within Normal Range") -> Above Average - Review Discount Policy
A9: =INDEX(tblModelCategory[category_name],MATCH("Laptops & Computers",tblModelCategory[category_name],0)) -> Laptops & Computers | B9: =SUMIFS(tblModelCategory[revenue],tblModelCategory[category_name],A9) -> 2977044772 | C9: =SUMIFS(tblModelCategory[catalog_value],tblModelCategory[category_name],A9) -> 3294481190 | D9: =SUMIFS(tblModelCategory[discount_leak],tblModelCategory[category_name],A9) -> 327405596 | E9: =D9/C9 -> 0.099380017 | F9: =IF(E9>$I$1,"Above Average - Review Discount Policy","Within Normal Range") -> Above Average - Review Discount Policy
A10: =INDEX(tblModelCategory[category_name],MATCH("Footwear",tblModelCategory[category_name],0)) -> Footwear | B10: =SUMIFS(tblModelCategory[revenue],tblModelCategory[category_name],A10) -> 218483178 | C10: =SUMIFS(tblModelCategory[catalog_value],tblModelCategory[category_name],A10) -> 241743290 | D10: =SUMIFS(tblModelCategory[discount_leak],tblModelCategory[category_name],A10) -> 24009501 | E10: =D10/C10 -> 0.099318169 | F10: =IF(E10>$I$1,"Above Average - Review Discount Policy","Within Normal Range") -> Above Average - Review Discount Policy
A11: =INDEX(tblModelCategory[category_name],MATCH("Furniture",tblModelCategory[category_name],0)) -> Furniture | B11: =SUMIFS(tblModelCategory[revenue],tblModelCategory[category_name],A11) -> 1907350207 | C11: =SUMIFS(tblModelCategory[catalog_value],tblModelCategory[category_name],A11) -> 2110496580 | D11: =SUMIFS(tblModelCategory[discount_leak],tblModelCategory[category_name],A11) -> 209518887 | E11: =D11/C11 -> 0.099274687 | F11: =IF(E11>$I$1,"Above Average - Review Discount Policy","Within Normal Range") -> Above Average - Review Discount Policy
A12: =INDEX(tblModelCategory[category_name],MATCH("Groceries & Staples",tblModelCategory[category_name],0)) -> Groceries & Staples | B12: =SUMIFS(tblModelCategory[revenue],tblModelCategory[category_name],A12) -> 45075426 | C12: =SUMIFS(tblModelCategory[catalog_value],tblModelCategory[category_name],A12) -> 49867370 | D12: =SUMIFS(tblModelCategory[discount_leak],tblModelCategory[category_name],A12) -> 4946330 | E12: =D12/C12 -> 0.099189711 | F12: =IF(E12>$I$1,"Above Average - Review Discount Policy","Within Normal Range") -> Above Average - Review Discount Policy
A13: =INDEX(tblModelCategory[category_name],MATCH("Women's Apparel",tblModelCategory[category_name],0)) -> Women's Apparel | B13: =SUMIFS(tblModelCategory[revenue],tblModelCategory[category_name],A13) -> 180387906 | C13: =SUMIFS(tblModelCategory[catalog_value],tblModelCategory[category_name],A13) -> 199503650 | D13: =SUMIFS(tblModelCategory[discount_leak],tblModelCategory[category_name],A13) -> 19724058 | E13: =D13/C13 -> 0.09886565 | F13: =IF(E13>$I$1,"Above Average - Review Discount Policy","Within Normal Range") -> Within Normal Range
A14: =INDEX(tblModelCategory[category_name],MATCH("Toys & Games",tblModelCategory[category_name],0)) -> Toys & Games | B14: =SUMIFS(tblModelCategory[revenue],tblModelCategory[category_name],A14) -> 152264378 | C14: =SUMIFS(tblModelCategory[catalog_value],tblModelCategory[category_name],A14) -> 168422050 | D14: =SUMIFS(tblModelCategory[discount_leak],tblModelCategory[category_name],A14) -> 16662928 | E14: =D14/C14 -> 0.098935549 | F14: =IF(E14>$I$1,"Above Average - Review Discount Policy","Within Normal Range") -> Within Normal Range
A15: =INDEX(tblModelCategory[category_name],MATCH("Home Audio",tblModelCategory[category_name],0)) -> Home Audio | B15: =SUMIFS(tblModelCategory[revenue],tblModelCategory[category_name],A15) -> 520527346 | C15: =SUMIFS(tblModelCategory[catalog_value],tblModelCategory[category_name],A15) -> 575620000 | D15: =SUMIFS(tblModelCategory[discount_leak],tblModelCategory[category_name],A15) -> 56856404 | E15: =D15/C15 -> 0.098774198 | F15: =IF(E15>$I$1,"Above Average - Review Discount Policy","Within Normal Range") -> Within Normal Range
A16: =INDEX(tblModelCategory[category_name],MATCH("Televisions",tblModelCategory[category_name],0)) -> Televisions | B16: =SUMIFS(tblModelCategory[revenue],tblModelCategory[category_name],A16) -> 2296118310 | C16: =SUMIFS(tblModelCategory[catalog_value],tblModelCategory[category_name],A16) -> 2538567220 | D16: =SUMIFS(tblModelCategory[discount_leak],tblModelCategory[category_name],A16) -> 250368359 | E16: =D16/C16 -> 0.098625854 | F16: =IF(E16>$I$1,"Above Average - Review Discount Policy","Within Normal Range") -> Within Normal Range
A17: =INDEX(tblModelCategory[category_name],MATCH("Festive & Gifting",tblModelCategory[category_name],0)) -> Festive & Gifting | B17: =SUMIFS(tblModelCategory[revenue],tblModelCategory[category_name],A17) -> 216122731 | C17: =SUMIFS(tblModelCategory[catalog_value],tblModelCategory[category_name],A17) -> 238954570 | D17: =SUMIFS(tblModelCategory[discount_leak],tblModelCategory[category_name],A17) -> 23569987 | E17: =D17/C17 -> 0.098637942 | F17: =IF(E17>$I$1,"Above Average - Review Discount Policy","Within Normal Range") -> Within Normal Range
A18: =INDEX(tblModelCategory[category_name],MATCH("Kitchen Appliances",tblModelCategory[category_name],0)) -> Kitchen Appliances | B18: =SUMIFS(tblModelCategory[revenue],tblModelCategory[category_name],A18) -> 602723939 | C18: =SUMIFS(tblModelCategory[catalog_value],tblModelCategory[category_name],A18) -> 666395200 | D18: =SUMIFS(tblModelCategory[discount_leak],tblModelCategory[category_name],A18) -> 65733883 | E18: =D18/C18 -> 0.098640991 | F18: =IF(E18>$I$1,"Above Average - Review Discount Policy","Within Normal Range") -> Within Normal Range
A19: =INDEX(tblModelCategory[category_name],MATCH("Refrigerators",tblModelCategory[category_name],0)) -> Refrigerators | B19: =SUMIFS(tblModelCategory[revenue],tblModelCategory[category_name],A19) -> 4382590644 | C19: =SUMIFS(tblModelCategory[catalog_value],tblModelCategory[category_name],A19) -> 4845220420 | D19: =SUMIFS(tblModelCategory[discount_leak],tblModelCategory[category_name],A19) -> 477412556 | E19: =D19/C19 -> 0.098532681 | F19: =IF(E19>$I$1,"Above Average - Review Discount Policy","Within Normal Range") -> Within Normal Range
A20: =INDEX(tblModelCategory[category_name],MATCH("Mobiles & Accessories",tblModelCategory[category_name],0)) -> Mobiles & Accessories | B20: =SUMIFS(tblModelCategory[revenue],tblModelCategory[category_name],A20) -> 1718375549 | C20: =SUMIFS(tblModelCategory[catalog_value],tblModelCategory[category_name],A20) -> 1899178170 | D20: =SUMIFS(tblModelCategory[discount_leak],tblModelCategory[category_name],A20) -> 186700048 | E20: =D20/C20 -> 0.098305705 | F20: =IF(E20>$I$1,"Above Average - Review Discount Policy","Within Normal Range") -> Within Normal Range
A21: =INDEX(tblModelCategory[category_name],MATCH("Heaters & Winter Appliances",tblModelCategory[category_name],0)) -> Heaters & Winter Appliances | B21: =SUMIFS(tblModelCategory[revenue],tblModelCategory[category_name],A21) -> 258134495 | C21: =SUMIFS(tblModelCategory[catalog_value],tblModelCategory[category_name],A21) -> 285298830 | D21: =SUMIFS(tblModelCategory[discount_leak],tblModelCategory[category_name],A21) -> 28051708 | E21: =D21/C21 -> 0.09832395 | F21: =IF(E21>$I$1,"Above Average - Review Discount Policy","Within Normal Range") -> Within Normal Range
A22: =INDEX(tblModelCategory[category_name],MATCH("Washing Machines",tblModelCategory[category_name],0)) -> Washing Machines | B22: =SUMIFS(tblModelCategory[revenue],tblModelCategory[category_name],A22) -> 1242288851 | C22: =SUMIFS(tblModelCategory[catalog_value],tblModelCategory[category_name],A22) -> 1372667370 | D22: =SUMIFS(tblModelCategory[discount_leak],tblModelCategory[category_name],A22) -> 134651075 | E22: =D22/C22 -> 0.098094468 | F22: =IF(E22>$I$1,"Above Average - Review Discount Policy","Within Normal Range") -> Within Normal Range
A23: =INDEX(tblModelCategory[category_name],MATCH("Home Decor",tblModelCategory[category_name],0)) -> Home Decor | B23: =SUMIFS(tblModelCategory[revenue],tblModelCategory[category_name],A23) -> 190662742 | C23: =SUMIFS(tblModelCategory[catalog_value],tblModelCategory[category_name],A23) -> 210602220 | D23: =SUMIFS(tblModelCategory[discount_leak],tblModelCategory[category_name],A23) -> 20606146 | E23: =D23/C23 -> 0.097843916 | F23: =IF(E23>$I$1,"Above Average - Review Discount Policy","Within Normal Range") -> Within Normal Range
A24: =INDEX(tblModelCategory[category_name],MATCH("Men's Apparel",tblModelCategory[category_name],0)) -> Men's Apparel | B24: =SUMIFS(tblModelCategory[revenue],tblModelCategory[category_name],A24) -> 174253220 | C24: =SUMIFS(tblModelCategory[catalog_value],tblModelCategory[category_name],A24) -> 192360750 | D24: =SUMIFS(tblModelCategory[discount_leak],tblModelCategory[category_name],A24) -> 18713357 | E24: =D24/C24 -> 0.097282616 | F24: =IF(E24>$I$1,"Above Average - Review Discount Policy","Within Normal Range") -> Within Normal Range

Sheet 06_KPI_Returns
A1: Q4 — Highest-return categories and Rs margin leakage from refunds | H1: Overall Avg Return Rate % | I1: =AVERAGE(tblModelCategory[return_rate]) -> 0.03835
A4: Category | B4: Order Lines | C4: Return Count | D4: Return Rate % | E4: Refund Leakage (Rs) | F4: Flag
A5: =INDEX(tblModelCategory[category_name],MATCH("Men's Apparel",tblModelCategory[category_name],0)) -> Men's Apparel | B5: =SUMIFS(tblModelCategory[lines],tblModelCategory[category_name],A5) -> 23457 | C5: =SUMIFS(tblModelCategory[return_count],tblModelCategory[category_name],A5) -> 1626 | D5: =C5/B5 -> 0.069318327 | E5: =SUMIFS(tblModelCategory[refund_amount],tblModelCategory[category_name],A5) -> 10202661 | F5: =IF(D5>$I$1,"Above Average - Investigate Return Reasons","Within Normal Range") -> Above Average - Investigate Return Reasons
A6: =INDEX(tblModelCategory[category_name],MATCH("Kids Apparel",tblModelCategory[category_name],0)) -> Kids Apparel | B6: =SUMIFS(tblModelCategory[lines],tblModelCategory[category_name],A6) -> 27448 | C6: =SUMIFS(tblModelCategory[return_count],tblModelCategory[category_name],A6) -> 1900 | D6: =C6/B6 -> 0.069221801 | E6: =SUMIFS(tblModelCategory[refund_amount],tblModelCategory[category_name],A6) -> 6606248 | F6: =IF(D6>$I$1,"Above Average - Investigate Return Reasons","Within Normal Range") -> Above Average - Investigate Return Reasons
A7: =INDEX(tblModelCategory[category_name],MATCH("Footwear",tblModelCategory[category_name],0)) -> Footwear | B7: =SUMIFS(tblModelCategory[lines],tblModelCategory[category_name],A7) -> 25921 | C7: =SUMIFS(tblModelCategory[return_count],tblModelCategory[category_name],A7) -> 1751 | D7: =C7/B7 -> 0.067551406 | E7: =SUMIFS(tblModelCategory[refund_amount],tblModelCategory[category_name],A7) -> 12659306 | F7: =IF(D7>$I$1,"Above Average - Investigate Return Reasons","Within Normal Range") -> Above Average - Investigate Return Reasons
A8: =INDEX(tblModelCategory[category_name],MATCH("Women's Apparel",tblModelCategory[category_name],0)) -> Women's Apparel | B8: =SUMIFS(tblModelCategory[lines],tblModelCategory[category_name],A8) -> 23635 | C8: =SUMIFS(tblModelCategory[return_count],tblModelCategory[category_name],A8) -> 1588 | D8: =C8/B8 -> 0.067188492 | E8: =SUMIFS(tblModelCategory[refund_amount],tblModelCategory[category_name],A8) -> 10512341 | F8: =IF(D8>$I$1,"Above Average - Investigate Return Reasons","Within Normal Range") -> Above Average - Investigate Return Reasons
